=== Build LinuxKit
[2017-11-23 04:58.57] Starting...
Cloning into '/tmp/with_clone908770b'...
done.
HEAD is now at dbb7e8dad kernel: Fixing kernel_perf and kernel_zfs build issue
[2017-11-23 04:58.59] Running "cp" "-p" "--" "/gcloud/ci-setup.sh" "/tmp/with_clone908770b/ci-setup.sh"
[2017-11-23 04:58.59] Building with timeout of 120 minutes
[2017-11-23 04:58.59] Running "/gcloud/create.py" "linuxkit-ci-4"
INFO:oauth2client.transport:Attempting refresh to obtain initial access_token
INFO:oauth2client.client:Refreshing access_token
INFO:root:Using source disk image https://www.googleapis.com/compute/v1/projects/moby-datakit-ci/global/images/linuxkit-ci-builder-4
INFO:root:Creating VM
WARNING:googleapiclient.http:Encountered 403 Forbidden with reason "rateLimitExceeded"
Traceback (most recent call last):
  File "/gcloud/create.py", line 43, in <module>
    resp = common.compute.instances().insert(body=config, project=common.project, zone=common.zone).execute()
  File "/usr/lib/python2.7/site-packages/oauth2client/_helpers.py", line 133, in positional_wrapper
    return wrapped(*args, **kwargs)
  File "/usr/lib/python2.7/site-packages/googleapiclient/http.py", line 840, in execute
    raise HttpError(resp, content, uri=self.uri)
googleapiclient.errors.HttpError: <HttpError 403 when requesting https://www.googleapis.com/compute/v1/projects/moby-datakit-ci/zones/europe-west1-b/instances?alt=json returned "Rate Limit Exceeded">
[2017-11-23 04:59.01] Removing test VM...
[2017-11-23 04:59.01] Running "/gcloud/destroy.py" "linuxkit-ci-4"
INFO:root:Destroying VM
INFO:oauth2client.transport:Attempting refresh to obtain initial access_token
INFO:oauth2client.client:Refreshing access_token
Traceback (most recent call last):
  File "/gcloud/destroy.py", line 12, in <module>
    resp = common.compute.instances().delete(instance=name, project=common.project, zone=common.zone).execute()
  File "/usr/lib/python2.7/site-packages/oauth2client/_helpers.py", line 133, in positional_wrapper
    return wrapped(*args, **kwargs)
  File "/usr/lib/python2.7/site-packages/googleapiclient/http.py", line 840, in execute
    raise HttpError(resp, content, uri=self.uri)
googleapiclient.errors.HttpError: <HttpError 404 when requesting https://www.googleapis.com/compute/v1/projects/moby-datakit-ci/zones/europe-west1-b/instances/linuxkit-ci-4?alt=json returned "The resource 'projects/moby-datakit-ci/zones/europe-west1-b/instances/linuxkit-ci-4' was not found">
[2017-11-23 04:59.02] Results directory "/tmp/linuxkit-320522ff/_results" not found, so not saving
[2017-11-23 04:59.02] Failed: Command "/gcloud/create.py" "linuxkit-ci-4" exited with status 1
