=== Test LinuxKit on GCP
[2017-07-18 16:33.19] Starting...
INFO:root:Connecting to storage
INFO:root:Getting bucket
INFO:root:Uploading /build-cache/b99ee2b554268b388b5a92f08cd25a554ced491e1157b5cf3f9a0820fdac488c -> linuxkit-ci-5.tar.gz
Traceback (most recent call last):
  File "/gcloud/test.py", line 29, in <module>
    blob.upload_from_filename(source_file_name)
  File "/usr/lib/python2.7/site-packages/google/cloud/storage/blob.py", line 934, in upload_from_filename
    size=total_bytes)
  File "/usr/lib/python2.7/site-packages/google/cloud/storage/blob.py", line 891, in upload_from_file
    client, file_obj, content_type, size, num_retries)
  File "/usr/lib/python2.7/site-packages/google/cloud/storage/blob.py", line 815, in _do_upload
    client, stream, content_type, size, num_retries)
  File "/usr/lib/python2.7/site-packages/google/cloud/storage/blob.py", line 654, in _do_multipart_upload
    transport, data, object_metadata, content_type)
  File "/usr/lib/python2.7/site-packages/google/resumable_media/requests/upload.py", line 97, in transmit
    retry_strategy=self._retry_strategy)
  File "/usr/lib/python2.7/site-packages/google/resumable_media/requests/_helpers.py", line 98, in http_request
    func, RequestsMixin._get_status_code, retry_strategy)
  File "/usr/lib/python2.7/site-packages/google/resumable_media/_helpers.py", line 147, in wait_and_retry
    response = func()
  File "/usr/lib/python2.7/site-packages/google/auth/transport/requests.py", line 179, in request
    method, url, data=data, headers=request_headers, **kwargs)
  File "/usr/lib/python2.7/site-packages/requests/sessions.py", line 502, in request
    resp = self.send(prep, **send_kwargs)
  File "/usr/lib/python2.7/site-packages/requests/sessions.py", line 612, in send
    r = adapter.send(request, **kwargs)
  File "/usr/lib/python2.7/site-packages/requests/adapters.py", line 514, in send
    raise SSLError(e, request=request)
requests.exceptions.SSLError: [SSL: CERTIFICATE_VERIFY_FAILED] certificate verify failed (_ssl.c:661)
[2017-07-18 16:33.20] Removing test VM...
[2017-07-18 16:33.20] Running "/gcloud/destroy.py" "linuxkit-ci-5"
INFO:root:Destroying VM
INFO:oauth2client.transport:Attempting refresh to obtain initial access_token
INFO:oauth2client.client:Refreshing access_token
Traceback (most recent call last):
  File "/gcloud/destroy.py", line 12, in <module>
    resp = common.compute.instances().delete(instance=name, project=common.project, zone=common.zone).execute()
  File "/usr/lib/python2.7/site-packages/oauth2client/_helpers.py", line 133, in positional_wrapper
    return wrapped(*args, **kwargs)
  File "/usr/lib/python2.7/site-packages/googleapiclient/http.py", line 840, in execute
    raise HttpError(resp, content, uri=self.uri)
googleapiclient.errors.HttpError: <HttpError 404 when requesting https://www.googleapis.com/compute/v1/projects/moby-datakit-ci/zones/europe-west1-b/instances/linuxkit-ci-5?alt=json returned "The resource 'projects/moby-datakit-ci/zones/europe-west1-b/instances/linuxkit-ci-5' was not found">
[2017-07-18 16:33.21] Failed: Command "/gcloud/test.py" "/build-cache/b99ee2b554268b388b5a92f08cd25a554ced491e1157b5cf3f9a0820fdac488c" "linuxkit-ci-5" exited with status 1
