=== Build LinuxKit
[2018-11-02 00:22.59] Starting...
Cloning into '/tmp/with_clone39293756'...
done.
HEAD is now at 58f94915d October 2018 development report
[2018-11-02 00:23.01] Running "cp" "-p" "--" "/gcloud/ci-setup.sh" "/tmp/with_clone39293756/ci-setup.sh"
[2018-11-02 00:23.01] Building with timeout of 120 minutes
[2018-11-02 00:23.01] Running "/gcloud/create.py" "linuxkit-ci-2"
INFO:oauth2client.transport:Attempting refresh to obtain initial access_token
INFO:oauth2client.client:Refreshing access_token
INFO:root:Using source disk image https://www.googleapis.com/compute/v1/projects/moby-datakit-ci/global/images/linuxkit-ci-builder-9
INFO:root:Creating VM
Traceback (most recent call last):
  File "/gcloud/create.py", line 44, in <module>
    resp = common.compute.instances().insert(body=config, project=common.project, zone=common.zone).execute()
  File "/usr/lib/python2.7/site-packages/googleapiclient/_helpers.py", line 130, in positional_wrapper
    return wrapped(*args, **kwargs)
  File "/usr/lib/python2.7/site-packages/googleapiclient/http.py", line 842, in execute
    raise HttpError(resp, content, uri=self.uri)
googleapiclient.errors.HttpError: <HttpError 409 when requesting https://www.googleapis.com/compute/v1/projects/moby-datakit-ci/zones/europe-west1-b/instances?alt=json returned "The resource 'projects/moby-datakit-ci/zones/europe-west1-b/instances/linuxkit-ci-2' already exists">
[2018-11-02 00:23.02] Removing test VM...
[2018-11-02 00:23.02] Running "/gcloud/destroy.py" "linuxkit-ci-2"
INFO:root:Destroying VM
INFO:oauth2client.transport:Attempting refresh to obtain initial access_token
INFO:oauth2client.client:Refreshing access_token
INFO:root:Waiting for zone operation to finish
INFO:root:Operation in progress... waiting...
[2018-11-02 00:23.09] Results directory "/tmp/linuxkit-155f41c/_results" not found, so not saving
[2018-11-02 00:23.09] Failed: Command "/gcloud/create.py" "linuxkit-ci-2" exited with status 1
